[2021-04-29 09:35:32 +0800] [23026] [INFO] Starting gunicorn 20.0.4
[2021-04-29 09:35:32 +0800] [23026] [INFO] Listening at: http://0.0.0.0:18000 (23026)
[2021-04-29 09:35:32 +0800] [23026] [INFO] Using worker: sync
[2021-04-29 09:35:32 +0800] [23029] [INFO] Booting worker with pid: 23029
[2021-04-29 09:35:32 +0800] [23030] [INFO] Booting worker with pid: 23030
[2021-04-29 09:35:34 +0800] [23030] [ERROR] Exception in worker process
Traceback (most recent call last):
  File "/home/dclab/miniconda3/envs/test/lib/python3.7/site-packages/gunicorn/arbiter.py", line 583, in spawn_worker
    worker.init_process()
  File "/home/dclab/miniconda3/envs/test/lib/python3.7/site-packages/gunicorn/workers/base.py", line 119, in init_process
    self.load_wsgi()
  File "/home/dclab/miniconda3/envs/test/lib/python3.7/site-packages/gunicorn/workers/base.py", line 144, in load_wsgi
    self.wsgi = self.app.wsgi()
  File "/home/dclab/miniconda3/envs/test/lib/python3.7/site-packages/gunicorn/app/base.py", line 67, in wsgi
    self.callable = self.load()
  File "/home/dclab/miniconda3/envs/test/lib/python3.7/site-packages/gunicorn/app/wsgiapp.py", line 49, in load
    return self.load_wsgiapp()
  File "/home/dclab/miniconda3/envs/test/lib/python3.7/site-packages/gunicorn/app/wsgiapp.py", line 39, in load_wsgiapp
    return util.import_app(self.app_uri)
  File "/home/dclab/miniconda3/envs/test/lib/python3.7/site-packages/gunicorn/util.py", line 358, in import_app
    mod = importlib.import_module(module)
  File "/home/dclab/miniconda3/envs/test/lib/python3.7/importlib/__init__.py", line 127, in import_module
    return _bootstrap._gcd_import(name[level:], package, level)
  File "<frozen importlib._bootstrap>", line 1006, in _gcd_import
  File "<frozen importlib._bootstrap>", line 983, in _find_and_load
  File "<frozen importlib._bootstrap>", line 967, in _find_and_load_unlocked
  File "<frozen importlib._bootstrap>", line 677, in _load_unlocked
  File "<frozen importlib._bootstrap_external>", line 728, in exec_module
  File "<frozen importlib._bootstrap>", line 219, in _call_with_frames_removed
  File "/home/dclab/ynpower/newynpower/ynpowerbackend/app.py", line 13, in <module>
    cors = CORS(app, resources='*', supports_credentials=True, send_wildcard=True)
  File "/home/dclab/miniconda3/envs/test/lib/python3.7/site-packages/flask_cors/extension.py", line 133, in __init__
    self.init_app(app, **kwargs)
  File "/home/dclab/miniconda3/envs/test/lib/python3.7/site-packages/flask_cors/extension.py", line 138, in init_app
    options = get_cors_options(app, self._options, kwargs)
  File "/home/dclab/miniconda3/envs/test/lib/python3.7/site-packages/flask_cors/core.py", line 300, in get_cors_options
    return serialize_options(options)
  File "/home/dclab/miniconda3/envs/test/lib/python3.7/site-packages/flask_cors/core.py", line 371, in serialize_options
    raise ValueError("Cannot use supports_credentials in conjunction with"
ValueError: Cannot use supports_credentials in conjunction withan origin string of '*'. See: http://www.w3.org/TR/cors/#resource-requests
[2021-04-29 09:35:34 +0800] [23029] [ERROR] Exception in worker process
Traceback (most recent call last):
  File "/home/dclab/miniconda3/envs/test/lib/python3.7/site-packages/gunicorn/arbiter.py", line 583, in spawn_worker
    worker.init_process()
  File "/home/dclab/miniconda3/envs/test/lib/python3.7/site-packages/gunicorn/workers/base.py", line 119, in init_process
    self.load_wsgi()
  File "/home/dclab/miniconda3/envs/test/lib/python3.7/site-packages/gunicorn/workers/base.py", line 144, in load_wsgi
    self.wsgi = self.app.wsgi()
  File "/home/dclab/miniconda3/envs/test/lib/python3.7/site-packages/gunicorn/app/base.py", line 67, in wsgi
    self.callable = self.load()
  File "/home/dclab/miniconda3/envs/test/lib/python3.7/site-packages/gunicorn/app/wsgiapp.py", line 49, in load
    return self.load_wsgiapp()
  File "/home/dclab/miniconda3/envs/test/lib/python3.7/site-packages/gunicorn/app/wsgiapp.py", line 39, in load_wsgiapp
    return util.import_app(self.app_uri)
  File "/home/dclab/miniconda3/envs/test/lib/python3.7/site-packages/gunicorn/util.py", line 358, in import_app
    mod = importlib.import_module(module)
  File "/home/dclab/miniconda3/envs/test/lib/python3.7/importlib/__init__.py", line 127, in import_module
    return _bootstrap._gcd_import(name[level:], package, level)
  File "<frozen importlib._bootstrap>", line 1006, in _gcd_import
  File "<frozen importlib._bootstrap>", line 983, in _find_and_load
  File "<frozen importlib._bootstrap>", line 967, in _find_and_load_unlocked
  File "<frozen importlib._bootstrap>", line 677, in _load_unlocked
  File "<frozen importlib._bootstrap_external>", line 728, in exec_module
  File "<frozen importlib._bootstrap>", line 219, in _call_with_frames_removed
  File "/home/dclab/ynpower/newynpower/ynpowerbackend/app.py", line 13, in <module>
    cors = CORS(app, resources='*', supports_credentials=True, send_wildcard=True)
  File "/home/dclab/miniconda3/envs/test/lib/python3.7/site-packages/flask_cors/extension.py", line 133, in __init__
    self.init_app(app, **kwargs)
  File "/home/dclab/miniconda3/envs/test/lib/python3.7/site-packages/flask_cors/extension.py", line 138, in init_app
    options = get_cors_options(app, self._options, kwargs)
  File "/home/dclab/miniconda3/envs/test/lib/python3.7/site-packages/flask_cors/core.py", line 300, in get_cors_options
    return serialize_options(options)
  File "/home/dclab/miniconda3/envs/test/lib/python3.7/site-packages/flask_cors/core.py", line 371, in serialize_options
    raise ValueError("Cannot use supports_credentials in conjunction with"
ValueError: Cannot use supports_credentials in conjunction withan origin string of '*'. See: http://www.w3.org/TR/cors/#resource-requests
[2021-04-29 09:35:34 +0800] [23030] [INFO] Worker exiting (pid: 23030)
[2021-04-29 09:35:34 +0800] [23029] [INFO] Worker exiting (pid: 23029)
Traceback (most recent call last):
  File "/home/dclab/miniconda3/envs/test/lib/python3.7/site-packages/gunicorn/arbiter.py", line 209, in run
    self.sleep()
  File "/home/dclab/miniconda3/envs/test/lib/python3.7/site-packages/gunicorn/arbiter.py", line 357, in sleep
    ready = select.select([self.PIPE[0]], [], [], 1.0)
  File "/home/dclab/miniconda3/envs/test/lib/python3.7/site-packages/gunicorn/arbiter.py", line 242, in handle_chld
    self.reap_workers()
  File "/home/dclab/miniconda3/envs/test/lib/python3.7/site-packages/gunicorn/arbiter.py", line 525, in reap_workers
    raise HaltServer(reason, self.WORKER_BOOT_ERROR)
gunicorn.errors.HaltServer: <HaltServer 'Worker failed to boot.' 3>

During handling of the above exception, another exception occurred:

Traceback (most recent call last):
  File "/home/dclab/miniconda3/envs/test/bin/gunicorn", line 11, in <module>
    sys.exit(run())
  File "/home/dclab/miniconda3/envs/test/lib/python3.7/site-packages/gunicorn/app/wsgiapp.py", line 58, in run
    WSGIApplication("%(prog)s [OPTIONS] [APP_MODULE]").run()
  File "/home/dclab/miniconda3/envs/test/lib/python3.7/site-packages/gunicorn/app/base.py", line 228, in run
    super().run()
  File "/home/dclab/miniconda3/envs/test/lib/python3.7/site-packages/gunicorn/app/base.py", line 72, in run
    Arbiter(self).run()
  File "/home/dclab/miniconda3/envs/test/lib/python3.7/site-packages/gunicorn/arbiter.py", line 229, in run
    self.halt(reason=inst.reason, exit_status=inst.exit_status)
  File "/home/dclab/miniconda3/envs/test/lib/python3.7/site-packages/gunicorn/arbiter.py", line 342, in halt
    self.stop()
  File "/home/dclab/miniconda3/envs/test/lib/python3.7/site-packages/gunicorn/arbiter.py", line 393, in stop
    time.sleep(0.1)
  File "/home/dclab/miniconda3/envs/test/lib/python3.7/site-packages/gunicorn/arbiter.py", line 242, in handle_chld
    self.reap_workers()
  File "/home/dclab/miniconda3/envs/test/lib/python3.7/site-packages/gunicorn/arbiter.py", line 525, in reap_workers
    raise HaltServer(reason, self.WORKER_BOOT_ERROR)
gunicorn.errors.HaltServer: <HaltServer 'Worker failed to boot.' 3>
